[2025-06-17T18:38:37.273+0000] {local_task_job_runner.py:123} INFO - ::group::Pre task execution logs
[2025-06-17T18:38:37.308+0000] {taskinstance.py:2614} INFO - Dependencies all met for dep_context=non-requeueable deps ti=<TaskInstance: fraud_detection_training.execute_training manual__2025-06-17T18:38:33.090215+00:00 [queued]>
[2025-06-17T18:38:37.333+0000] {taskinstance.py:2614} INFO - Dependencies all met for dep_context=requeueable deps ti=<TaskInstance: fraud_detection_training.execute_training manual__2025-06-17T18:38:33.090215+00:00 [queued]>
[2025-06-17T18:38:37.335+0000] {taskinstance.py:2867} INFO - Starting attempt 1 of 1
[2025-06-17T18:38:37.360+0000] {taskinstance.py:2890} INFO - Executing <Task(PythonOperator): execute_training> on 2025-06-17 18:38:33.090215+00:00
[2025-06-17T18:38:37.372+0000] {warnings.py:112} WARNING - /home/***/.local/lib/python3.12/site-packages/***/task/task_runner/standard_task_runner.py:70: DeprecationWarning: This process (pid=5426) is multi-threaded, use of fork() may lead to deadlocks in the child.
  pid = os.fork()

[2025-06-17T18:38:37.374+0000] {standard_task_runner.py:72} INFO - Started process 5427 to run task
[2025-06-17T18:38:37.375+0000] {standard_task_runner.py:104} INFO - Running: ['***', 'tasks', 'run', 'fraud_detection_training', 'execute_training', 'manual__2025-06-17T18:38:33.090215+00:00', '--job-id', '27', '--raw', '--subdir', 'DAGS_FOLDER/fraud_detection_training_dag.py', '--cfg-path', '/tmp/tmpb80octnj']
[2025-06-17T18:38:37.377+0000] {standard_task_runner.py:105} INFO - Job 27: Subtask execute_training
[2025-06-17T18:38:37.448+0000] {task_command.py:467} INFO - Running <TaskInstance: fraud_detection_training.execute_training manual__2025-06-17T18:38:33.090215+00:00 [running]> on host b6a56ce8a16d
[2025-06-17T18:38:37.581+0000] {taskinstance.py:3134} INFO - Exporting env vars: AIRFLOW_CTX_DAG_OWNER='Jasjot Parmar' AIRFLOW_CTX_DAG_ID='fraud_detection_training' AIRFLOW_CTX_TASK_ID='execute_training' AIRFLOW_CTX_EXECUTION_DATE='2025-06-17T18:38:33.090215+00:00' AIRFLOW_CTX_TRY_NUMBER='1' AIRFLOW_CTX_DAG_RUN_ID='manual__2025-06-17T18:38:33.090215+00:00'
[2025-06-17T18:38:37.583+0000] {taskinstance.py:732} INFO - ::endgroup::
[2025-06-17T18:38:37.604+0000] {fraud_detection_training_dag.py:23} INFO - Initializing fraud detection training...
[2025-06-17T18:38:37.748+0000] {fraud_detection_training_dag.py:26} INFO - Imported FraudDetectionTraining successfully.
[2025-06-17T18:38:37.749+0000] {fraud_detection_training_dag.py:34} ERROR - Training failed: str expected, not tuple
Traceback (most recent call last):
  File "/opt/airflow/dags/fraud_detection_training_dag.py", line 28, in train_model
    trainer = FraudDetectionTraining()
              ^^^^^^^^^^^^^^^^^^^^^^^^
  File "/opt/airflow/dags/fraud_detection_training.py", line 20, in __init__
    os.environ['GIT_PYTHON_REFRESH'] = 'quiet',
    ~~~~~~~~~~^^^^^^^^^^^^^^^^^^^^^^
  File "<frozen os>", line 719, in __setitem__
  File "<frozen os>", line 793, in encode
TypeError: str expected, not tuple
[2025-06-17T18:38:37.777+0000] {taskinstance.py:3313} ERROR - Task failed with exception
Traceback (most recent call last):
  File "/opt/airflow/dags/fraud_detection_training_dag.py", line 28, in train_model
    trainer = FraudDetectionTraining()
              ^^^^^^^^^^^^^^^^^^^^^^^^
  File "/opt/airflow/dags/fraud_detection_training.py", line 20, in __init__
    os.environ['GIT_PYTHON_REFRESH'] = 'quiet',
    ~~~~~~~~~~^^^^^^^^^^^^^^^^^^^^^^
  File "<frozen os>", line 719, in __setitem__
  File "<frozen os>", line 793, in encode
TypeError: str expected, not tuple

During handling of the above exception, another exception occurred:

Traceback (most recent call last):
  File "/home/airflow/.local/lib/python3.12/site-packages/airflow/models/taskinstance.py", line 763, in _execute_task
    result = _execute_callable(context=context, **execute_callable_kwargs)
             ^^^^^^^^^^^^^^^^^^^^^^^^^^^^^^^^^^^^^^^^^^^^^^^^^^^^^^^^^^^^^
  File "/home/airflow/.local/lib/python3.12/site-packages/airflow/models/taskinstance.py", line 734, in _execute_callable
    return ExecutionCallableRunner(
           ^^^^^^^^^^^^^^^^^^^^^^^^
  File "/home/airflow/.local/lib/python3.12/site-packages/airflow/utils/operator_helpers.py", line 252, in run
    return self.func(*args, **kwargs)
           ^^^^^^^^^^^^^^^^^^^^^^^^^^
  File "/home/airflow/.local/lib/python3.12/site-packages/airflow/models/baseoperator.py", line 424, in wrapper
    return func(self, *args, **kwargs)
           ^^^^^^^^^^^^^^^^^^^^^^^^^^^
  File "/home/airflow/.local/lib/python3.12/site-packages/airflow/operators/python.py", line 238, in execute
    return_value = self.execute_callable()
                   ^^^^^^^^^^^^^^^^^^^^^^^
  File "/home/airflow/.local/lib/python3.12/site-packages/airflow/operators/python.py", line 256, in execute_callable
    return runner.run(*self.op_args, **self.op_kwargs)
           ^^^^^^^^^^^^^^^^^^^^^^^^^^^^^^^^^^^^^^^^^^^
  File "/home/airflow/.local/lib/python3.12/site-packages/airflow/utils/operator_helpers.py", line 252, in run
    return self.func(*args, **kwargs)
           ^^^^^^^^^^^^^^^^^^^^^^^^^^
  File "/opt/airflow/dags/fraud_detection_training_dag.py", line 35, in train_model
    raise AirflowException(f'Model training failed: {str(e)}')
airflow.exceptions.AirflowException: Model training failed: str expected, not tuple
[2025-06-17T18:38:37.789+0000] {taskinstance.py:1226} INFO - Marking task as FAILED. dag_id=fraud_detection_training, task_id=execute_training, run_id=manual__2025-06-17T18:38:33.090215+00:00, execution_date=20250617T183833, start_date=20250617T183837, end_date=20250617T183837
[2025-06-17T18:38:37.833+0000] {taskinstance.py:341} INFO - ::group::Post task execution logs
[2025-06-17T18:38:37.834+0000] {standard_task_runner.py:124} ERROR - Failed to execute job 27 for task execute_training (Model training failed: str expected, not tuple; 5427)
Traceback (most recent call last):
  File "/opt/airflow/dags/fraud_detection_training_dag.py", line 28, in train_model
    trainer = FraudDetectionTraining()
              ^^^^^^^^^^^^^^^^^^^^^^^^
  File "/opt/airflow/dags/fraud_detection_training.py", line 20, in __init__
    os.environ['GIT_PYTHON_REFRESH'] = 'quiet',
    ~~~~~~~~~~^^^^^^^^^^^^^^^^^^^^^^
  File "<frozen os>", line 719, in __setitem__
  File "<frozen os>", line 793, in encode
TypeError: str expected, not tuple

During handling of the above exception, another exception occurred:

Traceback (most recent call last):
  File "/home/airflow/.local/lib/python3.12/site-packages/airflow/task/task_runner/standard_task_runner.py", line 117, in _start_by_fork
    ret = args.func(args, dag=self.dag)
          ^^^^^^^^^^^^^^^^^^^^^^^^^^^^^
  File "/home/airflow/.local/lib/python3.12/site-packages/airflow/cli/cli_config.py", line 49, in command
    return func(*args, **kwargs)
           ^^^^^^^^^^^^^^^^^^^^^
  File "/home/airflow/.local/lib/python3.12/site-packages/airflow/utils/cli.py", line 116, in wrapper
    return f(*args, **kwargs)
           ^^^^^^^^^^^^^^^^^^
  File "/home/airflow/.local/lib/python3.12/site-packages/airflow/cli/commands/task_command.py", line 483, in task_run
    task_return_code = _run_task_by_selected_method(args, _dag, ti)
                       ^^^^^^^^^^^^^^^^^^^^^^^^^^^^^^^^^^^^^^^^^^^^
  File "/home/airflow/.local/lib/python3.12/site-packages/airflow/cli/commands/task_command.py", line 256, in _run_task_by_selected_method
    return _run_raw_task(args, ti)
           ^^^^^^^^^^^^^^^^^^^^^^^
  File "/home/airflow/.local/lib/python3.12/site-packages/airflow/cli/commands/task_command.py", line 341, in _run_raw_task
    return ti._run_raw_task(
           ^^^^^^^^^^^^^^^^^
  File "/home/airflow/.local/lib/python3.12/site-packages/airflow/utils/session.py", line 97, in wrapper
    return func(*args, session=session, **kwargs)
           ^^^^^^^^^^^^^^^^^^^^^^^^^^^^^^^^^^^^^^
  File "/home/airflow/.local/lib/python3.12/site-packages/airflow/models/taskinstance.py", line 3006, in _run_raw_task
    return _run_raw_task(
           ^^^^^^^^^^^^^^
  File "/home/airflow/.local/lib/python3.12/site-packages/airflow/models/taskinstance.py", line 274, in _run_raw_task
    TaskInstance._execute_task_with_callbacks(
  File "/home/airflow/.local/lib/python3.12/site-packages/airflow/models/taskinstance.py", line 3161, in _execute_task_with_callbacks
    result = self._execute_task(context, task_orig)
             ^^^^^^^^^^^^^^^^^^^^^^^^^^^^^^^^^^^^^^
  File "/home/airflow/.local/lib/python3.12/site-packages/airflow/models/taskinstance.py", line 3185, in _execute_task
    return _execute_task(self, context, task_orig)
           ^^^^^^^^^^^^^^^^^^^^^^^^^^^^^^^^^^^^^^^
  File "/home/airflow/.local/lib/python3.12/site-packages/airflow/models/taskinstance.py", line 763, in _execute_task
    result = _execute_callable(context=context, **execute_callable_kwargs)
             ^^^^^^^^^^^^^^^^^^^^^^^^^^^^^^^^^^^^^^^^^^^^^^^^^^^^^^^^^^^^^
  File "/home/airflow/.local/lib/python3.12/site-packages/airflow/models/taskinstance.py", line 734, in _execute_callable
    return ExecutionCallableRunner(
           ^^^^^^^^^^^^^^^^^^^^^^^^
  File "/home/airflow/.local/lib/python3.12/site-packages/airflow/utils/operator_helpers.py", line 252, in run
    return self.func(*args, **kwargs)
           ^^^^^^^^^^^^^^^^^^^^^^^^^^
  File "/home/airflow/.local/lib/python3.12/site-packages/airflow/models/baseoperator.py", line 424, in wrapper
    return func(self, *args, **kwargs)
           ^^^^^^^^^^^^^^^^^^^^^^^^^^^
  File "/home/airflow/.local/lib/python3.12/site-packages/airflow/operators/python.py", line 238, in execute
    return_value = self.execute_callable()
                   ^^^^^^^^^^^^^^^^^^^^^^^
  File "/home/airflow/.local/lib/python3.12/site-packages/airflow/operators/python.py", line 256, in execute_callable
    return runner.run(*self.op_args, **self.op_kwargs)
           ^^^^^^^^^^^^^^^^^^^^^^^^^^^^^^^^^^^^^^^^^^^
  File "/home/airflow/.local/lib/python3.12/site-packages/airflow/utils/operator_helpers.py", line 252, in run
    return self.func(*args, **kwargs)
           ^^^^^^^^^^^^^^^^^^^^^^^^^^
  File "/opt/airflow/dags/fraud_detection_training_dag.py", line 35, in train_model
    raise AirflowException(f'Model training failed: {str(e)}')
airflow.exceptions.AirflowException: Model training failed: str expected, not tuple
[2025-06-17T18:38:37.873+0000] {local_task_job_runner.py:266} INFO - Task exited with return code 1
[2025-06-17T18:38:37.910+0000] {taskinstance.py:3901} INFO - 1 downstream tasks scheduled from follow-on schedule check
[2025-06-17T18:38:37.915+0000] {local_task_job_runner.py:245} INFO - ::endgroup::
