[2025-07-21T03:00:04.735+0000] {local_task_job_runner.py:123} INFO - ::group::Pre task execution logs
[2025-07-21T03:00:04.763+0000] {taskinstance.py:2614} INFO - Dependencies all met for dep_context=non-requeueable deps ti=<TaskInstance: fraud_detection_training.execute_training scheduled__2025-07-20T03:00:00+00:00 [queued]>
[2025-07-21T03:00:04.773+0000] {taskinstance.py:2614} INFO - Dependencies all met for dep_context=requeueable deps ti=<TaskInstance: fraud_detection_training.execute_training scheduled__2025-07-20T03:00:00+00:00 [queued]>
[2025-07-21T03:00:04.774+0000] {taskinstance.py:2867} INFO - Starting attempt 1 of 1
[2025-07-21T03:00:04.787+0000] {taskinstance.py:2890} INFO - Executing <Task(PythonOperator): execute_training> on 2025-07-20 03:00:00+00:00
[2025-07-21T03:00:04.795+0000] {warnings.py:112} WARNING - /home/***/.local/lib/python3.12/site-packages/***/task/task_runner/standard_task_runner.py:70: DeprecationWarning: This process (pid=7293) is multi-threaded, use of fork() may lead to deadlocks in the child.
  pid = os.fork()

[2025-07-21T03:00:04.797+0000] {standard_task_runner.py:104} INFO - Running: ['***', 'tasks', 'run', 'fraud_detection_training', 'execute_training', 'scheduled__2025-07-20T03:00:00+00:00', '--job-id', '208', '--raw', '--subdir', 'DAGS_FOLDER/fraud_detection_training_dag.py', '--cfg-path', '/tmp/tmpodpye6l5']
[2025-07-21T03:00:04.800+0000] {standard_task_runner.py:72} INFO - Started process 7294 to run task
[2025-07-21T03:00:04.800+0000] {standard_task_runner.py:105} INFO - Job 208: Subtask execute_training
[2025-07-21T03:00:04.840+0000] {task_command.py:467} INFO - Running <TaskInstance: fraud_detection_training.execute_training scheduled__2025-07-20T03:00:00+00:00 [running]> on host 962ad35554cb
[2025-07-21T03:00:04.922+0000] {taskinstance.py:3134} INFO - Exporting env vars: AIRFLOW_CTX_DAG_OWNER='Jasjot Parmar' AIRFLOW_CTX_DAG_ID='fraud_detection_training' AIRFLOW_CTX_TASK_ID='execute_training' AIRFLOW_CTX_EXECUTION_DATE='2025-07-20T03:00:00+00:00' AIRFLOW_CTX_TRY_NUMBER='1' AIRFLOW_CTX_DAG_RUN_ID='scheduled__2025-07-20T03:00:00+00:00'
[2025-07-21T03:00:04.924+0000] {taskinstance.py:732} INFO - ::endgroup::
[2025-07-21T03:00:04.947+0000] {fraud_detection_training_dag.py:23} INFO - Initializing fraud detection training...
[2025-07-21T03:00:11.355+0000] {fraud_detection_training_dag.py:26} INFO - Imported FraudDetectionTraining successfully.
[2025-07-21T03:00:11.392+0000] {fraud_detection_training.py:75} INFO - Configuration loaded successfully
[2025-07-21T03:00:12.453+0000] {fraud_detection_training.py:116} ERROR - Minio connection failed: Invalid endpoint: ${S3_ENDPOINT_URL}
[2025-07-21T03:00:12.480+0000] {fraud_detection_training_dag.py:29} INFO - Trainer initialized successfully.
[2025-07-21T03:00:12.480+0000] {fraud_detection_training.py:397} INFO - Starting model training process...
[2025-07-21T03:00:12.481+0000] {fraud_detection_training.py:122} INFO - Connecting to Kafka Topic: transactions
[2025-07-21T03:00:12.483+0000] {conn.py:1516} WARNING - DNS lookup failed for ${KAFKA_BOOTSTRAP_SERVERS}:9092, exception was [Errno -2] Name or service not known. Is your advertised.listeners (called advertised.host.name before Kafka 9) correct and resolvable?
[2025-07-21T03:00:12.483+0000] {conn.py:323} ERROR - <BrokerConnection client_id=kafka-python-2.2.15, node_id=bootstrap-0 host=${KAFKA_BOOTSTRAP_SERVERS}:9092 <connecting> [unspecified None]>: DNS lookup failed for ${KAFKA_BOOTSTRAP_SERVERS}:9092 (0)
[2025-07-21T03:00:12.484+0000] {conn.py:945} ERROR - <BrokerConnection client_id=kafka-python-2.2.15, node_id=bootstrap-0 host=${KAFKA_BOOTSTRAP_SERVERS}:9092 <connecting> [unspecified None]>: Closing connection. KafkaConnectionError: DNS failure
[2025-07-21T03:00:12.484+0000] {client_async.py:1049} WARNING - No node available during check_version; sleeping 0.06 secs
[2025-07-21T03:00:12.544+0000] {conn.py:1516} WARNING - DNS lookup failed for ${KAFKA_BOOTSTRAP_SERVERS}:9092, exception was [Errno -2] Name or service not known. Is your advertised.listeners (called advertised.host.name before Kafka 9) correct and resolvable?
[2025-07-21T03:00:12.545+0000] {conn.py:323} ERROR - <BrokerConnection client_id=kafka-python-2.2.15, node_id=bootstrap-0 host=${KAFKA_BOOTSTRAP_SERVERS}:9092 <connecting> [unspecified None]>: DNS lookup failed for ${KAFKA_BOOTSTRAP_SERVERS}:9092 (0)
[2025-07-21T03:00:12.546+0000] {conn.py:945} ERROR - <BrokerConnection client_id=kafka-python-2.2.15, node_id=bootstrap-0 host=${KAFKA_BOOTSTRAP_SERVERS}:9092 <connecting> [unspecified None]>: Closing connection. KafkaConnectionError: DNS failure
[2025-07-21T03:00:12.546+0000] {client_async.py:1049} WARNING - No node available during check_version; sleeping 0.09 secs
[2025-07-21T03:00:12.639+0000] {conn.py:1516} WARNING - DNS lookup failed for ${KAFKA_BOOTSTRAP_SERVERS}:9092, exception was [Errno -2] Name or service not known. Is your advertised.listeners (called advertised.host.name before Kafka 9) correct and resolvable?
[2025-07-21T03:00:12.640+0000] {conn.py:323} ERROR - <BrokerConnection client_id=kafka-python-2.2.15, node_id=bootstrap-0 host=${KAFKA_BOOTSTRAP_SERVERS}:9092 <connecting> [unspecified None]>: DNS lookup failed for ${KAFKA_BOOTSTRAP_SERVERS}:9092 (0)
[2025-07-21T03:00:12.640+0000] {conn.py:945} ERROR - <BrokerConnection client_id=kafka-python-2.2.15, node_id=bootstrap-0 host=${KAFKA_BOOTSTRAP_SERVERS}:9092 <connecting> [unspecified None]>: Closing connection. KafkaConnectionError: DNS failure
[2025-07-21T03:00:12.641+0000] {client_async.py:1049} WARNING - No node available during check_version; sleeping 0.18 secs
[2025-07-21T03:00:12.823+0000] {conn.py:1516} WARNING - DNS lookup failed for ${KAFKA_BOOTSTRAP_SERVERS}:9092, exception was [Errno -2] Name or service not known. Is your advertised.listeners (called advertised.host.name before Kafka 9) correct and resolvable?
[2025-07-21T03:00:12.824+0000] {conn.py:323} ERROR - <BrokerConnection client_id=kafka-python-2.2.15, node_id=bootstrap-0 host=${KAFKA_BOOTSTRAP_SERVERS}:9092 <connecting> [unspecified None]>: DNS lookup failed for ${KAFKA_BOOTSTRAP_SERVERS}:9092 (0)
[2025-07-21T03:00:12.824+0000] {conn.py:945} ERROR - <BrokerConnection client_id=kafka-python-2.2.15, node_id=bootstrap-0 host=${KAFKA_BOOTSTRAP_SERVERS}:9092 <connecting> [unspecified None]>: Closing connection. KafkaConnectionError: DNS failure
[2025-07-21T03:00:12.825+0000] {client_async.py:1049} WARNING - No node available during check_version; sleeping 0.37 secs
[2025-07-21T03:00:13.197+0000] {conn.py:1516} WARNING - DNS lookup failed for ${KAFKA_BOOTSTRAP_SERVERS}:9092, exception was [Errno -2] Name or service not known. Is your advertised.listeners (called advertised.host.name before Kafka 9) correct and resolvable?
[2025-07-21T03:00:13.198+0000] {conn.py:323} ERROR - <BrokerConnection client_id=kafka-python-2.2.15, node_id=bootstrap-0 host=${KAFKA_BOOTSTRAP_SERVERS}:9092 <connecting> [unspecified None]>: DNS lookup failed for ${KAFKA_BOOTSTRAP_SERVERS}:9092 (0)
[2025-07-21T03:00:13.200+0000] {conn.py:945} ERROR - <BrokerConnection client_id=kafka-python-2.2.15, node_id=bootstrap-0 host=${KAFKA_BOOTSTRAP_SERVERS}:9092 <connecting> [unspecified None]>: Closing connection. KafkaConnectionError: DNS failure
[2025-07-21T03:00:13.203+0000] {client_async.py:1049} WARNING - No node available during check_version; sleeping 0.66 secs
[2025-07-21T03:00:13.864+0000] {conn.py:1516} WARNING - DNS lookup failed for ${KAFKA_BOOTSTRAP_SERVERS}:9092, exception was [Errno -2] Name or service not known. Is your advertised.listeners (called advertised.host.name before Kafka 9) correct and resolvable?
[2025-07-21T03:00:13.866+0000] {conn.py:323} ERROR - <BrokerConnection client_id=kafka-python-2.2.15, node_id=bootstrap-0 host=${KAFKA_BOOTSTRAP_SERVERS}:9092 <connecting> [unspecified None]>: DNS lookup failed for ${KAFKA_BOOTSTRAP_SERVERS}:9092 (0)
[2025-07-21T03:00:13.866+0000] {conn.py:945} ERROR - <BrokerConnection client_id=kafka-python-2.2.15, node_id=bootstrap-0 host=${KAFKA_BOOTSTRAP_SERVERS}:9092 <connecting> [unspecified None]>: Closing connection. KafkaConnectionError: DNS failure
[2025-07-21T03:00:13.867+0000] {client_async.py:1049} WARNING - No node available during check_version; sleeping 0.62 secs
[2025-07-21T03:00:14.483+0000] {fraud_detection_training.py:160} ERROR - Failed to read data from Kafka: NoBrokersAvailable
Traceback (most recent call last):
  File "/opt/airflow/dags/fraud_detection_training.py", line 125, in read_from_kafka
    consumer = KafkaConsumer(
               ^^^^^^^^^^^^^^
  File "/home/airflow/.local/lib/python3.12/site-packages/kafka/consumer/group.py", line 387, in __init__
    self._client = self.config['kafka_client'](metrics=self._metrics, **self.config)
                   ^^^^^^^^^^^^^^^^^^^^^^^^^^^^^^^^^^^^^^^^^^^^^^^^^^^^^^^^^^^^^^^^^
  File "/home/airflow/.local/lib/python3.12/site-packages/kafka/client_async.py", line 262, in __init__
    self.config['api_version'] = self.check_version()
                                 ^^^^^^^^^^^^^^^^^^^^
  File "/home/airflow/.local/lib/python3.12/site-packages/kafka/client_async.py", line 1074, in check_version
    raise Errors.NoBrokersAvailable()
kafka.errors.NoBrokersAvailable: NoBrokersAvailable
[2025-07-21T03:00:14.490+0000] {fraud_detection_training.py:675} ERROR - Training failed: NoBrokersAvailable
Traceback (most recent call last):
  File "/opt/airflow/dags/fraud_detection_training.py", line 400, in train_model
    df = self.read_from_kafka()
         ^^^^^^^^^^^^^^^^^^^^^^
  File "/opt/airflow/dags/fraud_detection_training.py", line 125, in read_from_kafka
    consumer = KafkaConsumer(
               ^^^^^^^^^^^^^^
  File "/home/airflow/.local/lib/python3.12/site-packages/kafka/consumer/group.py", line 387, in __init__
    self._client = self.config['kafka_client'](metrics=self._metrics, **self.config)
                   ^^^^^^^^^^^^^^^^^^^^^^^^^^^^^^^^^^^^^^^^^^^^^^^^^^^^^^^^^^^^^^^^^
  File "/home/airflow/.local/lib/python3.12/site-packages/kafka/client_async.py", line 262, in __init__
    self.config['api_version'] = self.check_version()
                                 ^^^^^^^^^^^^^^^^^^^^
  File "/home/airflow/.local/lib/python3.12/site-packages/kafka/client_async.py", line 1074, in check_version
    raise Errors.NoBrokersAvailable()
kafka.errors.NoBrokersAvailable: NoBrokersAvailable
[2025-07-21T03:00:14.492+0000] {fraud_detection_training_dag.py:37} ERROR - Training failed: NoBrokersAvailable
Traceback (most recent call last):
  File "/opt/airflow/dags/fraud_detection_training_dag.py", line 32, in train_model
    model, precision = trainer.train_model()
                       ^^^^^^^^^^^^^^^^^^^^^
  File "/opt/airflow/dags/fraud_detection_training.py", line 400, in train_model
    df = self.read_from_kafka()
         ^^^^^^^^^^^^^^^^^^^^^^
  File "/opt/airflow/dags/fraud_detection_training.py", line 125, in read_from_kafka
    consumer = KafkaConsumer(
               ^^^^^^^^^^^^^^
  File "/home/airflow/.local/lib/python3.12/site-packages/kafka/consumer/group.py", line 387, in __init__
    self._client = self.config['kafka_client'](metrics=self._metrics, **self.config)
                   ^^^^^^^^^^^^^^^^^^^^^^^^^^^^^^^^^^^^^^^^^^^^^^^^^^^^^^^^^^^^^^^^^
  File "/home/airflow/.local/lib/python3.12/site-packages/kafka/client_async.py", line 262, in __init__
    self.config['api_version'] = self.check_version()
                                 ^^^^^^^^^^^^^^^^^^^^
  File "/home/airflow/.local/lib/python3.12/site-packages/kafka/client_async.py", line 1074, in check_version
    raise Errors.NoBrokersAvailable()
kafka.errors.NoBrokersAvailable: NoBrokersAvailable
[2025-07-21T03:00:14.508+0000] {taskinstance.py:3313} ERROR - Task failed with exception
Traceback (most recent call last):
  File "/opt/airflow/dags/fraud_detection_training_dag.py", line 32, in train_model
    model, precision = trainer.train_model()
                       ^^^^^^^^^^^^^^^^^^^^^
  File "/opt/airflow/dags/fraud_detection_training.py", line 400, in train_model
    df = self.read_from_kafka()
         ^^^^^^^^^^^^^^^^^^^^^^
  File "/opt/airflow/dags/fraud_detection_training.py", line 125, in read_from_kafka
    consumer = KafkaConsumer(
               ^^^^^^^^^^^^^^
  File "/home/airflow/.local/lib/python3.12/site-packages/kafka/consumer/group.py", line 387, in __init__
    self._client = self.config['kafka_client'](metrics=self._metrics, **self.config)
                   ^^^^^^^^^^^^^^^^^^^^^^^^^^^^^^^^^^^^^^^^^^^^^^^^^^^^^^^^^^^^^^^^^
  File "/home/airflow/.local/lib/python3.12/site-packages/kafka/client_async.py", line 262, in __init__
    self.config['api_version'] = self.check_version()
                                 ^^^^^^^^^^^^^^^^^^^^
  File "/home/airflow/.local/lib/python3.12/site-packages/kafka/client_async.py", line 1074, in check_version
    raise Errors.NoBrokersAvailable()
kafka.errors.NoBrokersAvailable: NoBrokersAvailable

During handling of the above exception, another exception occurred:

Traceback (most recent call last):
  File "/home/airflow/.local/lib/python3.12/site-packages/airflow/models/taskinstance.py", line 763, in _execute_task
    result = _execute_callable(context=context, **execute_callable_kwargs)
             ^^^^^^^^^^^^^^^^^^^^^^^^^^^^^^^^^^^^^^^^^^^^^^^^^^^^^^^^^^^^^
  File "/home/airflow/.local/lib/python3.12/site-packages/airflow/models/taskinstance.py", line 734, in _execute_callable
    return ExecutionCallableRunner(
           ^^^^^^^^^^^^^^^^^^^^^^^^
  File "/home/airflow/.local/lib/python3.12/site-packages/airflow/utils/operator_helpers.py", line 252, in run
    return self.func(*args, **kwargs)
           ^^^^^^^^^^^^^^^^^^^^^^^^^^
  File "/home/airflow/.local/lib/python3.12/site-packages/airflow/models/baseoperator.py", line 424, in wrapper
    return func(self, *args, **kwargs)
           ^^^^^^^^^^^^^^^^^^^^^^^^^^^
  File "/home/airflow/.local/lib/python3.12/site-packages/airflow/operators/python.py", line 238, in execute
    return_value = self.execute_callable()
                   ^^^^^^^^^^^^^^^^^^^^^^^
  File "/home/airflow/.local/lib/python3.12/site-packages/airflow/operators/python.py", line 256, in execute_callable
    return runner.run(*self.op_args, **self.op_kwargs)
           ^^^^^^^^^^^^^^^^^^^^^^^^^^^^^^^^^^^^^^^^^^^
  File "/home/airflow/.local/lib/python3.12/site-packages/airflow/utils/operator_helpers.py", line 252, in run
    return self.func(*args, **kwargs)
           ^^^^^^^^^^^^^^^^^^^^^^^^^^
  File "/opt/airflow/dags/fraud_detection_training_dag.py", line 38, in train_model
    raise AirflowException(f'Model training failed: {str(e)}')
airflow.exceptions.AirflowException: Model training failed: NoBrokersAvailable
[2025-07-21T03:00:14.517+0000] {taskinstance.py:1226} INFO - Marking task as FAILED. dag_id=fraud_detection_training, task_id=execute_training, run_id=scheduled__2025-07-20T03:00:00+00:00, execution_date=20250720T030000, start_date=20250721T030004, end_date=20250721T030014
[2025-07-21T03:00:14.543+0000] {taskinstance.py:341} INFO - ::group::Post task execution logs
[2025-07-21T03:00:14.544+0000] {standard_task_runner.py:124} ERROR - Failed to execute job 208 for task execute_training (Model training failed: NoBrokersAvailable; 7294)
Traceback (most recent call last):
  File "/opt/airflow/dags/fraud_detection_training_dag.py", line 32, in train_model
    model, precision = trainer.train_model()
                       ^^^^^^^^^^^^^^^^^^^^^
  File "/opt/airflow/dags/fraud_detection_training.py", line 400, in train_model
    df = self.read_from_kafka()
         ^^^^^^^^^^^^^^^^^^^^^^
  File "/opt/airflow/dags/fraud_detection_training.py", line 125, in read_from_kafka
    consumer = KafkaConsumer(
               ^^^^^^^^^^^^^^
  File "/home/airflow/.local/lib/python3.12/site-packages/kafka/consumer/group.py", line 387, in __init__
    self._client = self.config['kafka_client'](metrics=self._metrics, **self.config)
                   ^^^^^^^^^^^^^^^^^^^^^^^^^^^^^^^^^^^^^^^^^^^^^^^^^^^^^^^^^^^^^^^^^
  File "/home/airflow/.local/lib/python3.12/site-packages/kafka/client_async.py", line 262, in __init__
    self.config['api_version'] = self.check_version()
                                 ^^^^^^^^^^^^^^^^^^^^
  File "/home/airflow/.local/lib/python3.12/site-packages/kafka/client_async.py", line 1074, in check_version
    raise Errors.NoBrokersAvailable()
kafka.errors.NoBrokersAvailable: NoBrokersAvailable

During handling of the above exception, another exception occurred:

Traceback (most recent call last):
  File "/home/airflow/.local/lib/python3.12/site-packages/airflow/task/task_runner/standard_task_runner.py", line 117, in _start_by_fork
    ret = args.func(args, dag=self.dag)
          ^^^^^^^^^^^^^^^^^^^^^^^^^^^^^
  File "/home/airflow/.local/lib/python3.12/site-packages/airflow/cli/cli_config.py", line 49, in command
    return func(*args, **kwargs)
           ^^^^^^^^^^^^^^^^^^^^^
  File "/home/airflow/.local/lib/python3.12/site-packages/airflow/utils/cli.py", line 116, in wrapper
    return f(*args, **kwargs)
           ^^^^^^^^^^^^^^^^^^
  File "/home/airflow/.local/lib/python3.12/site-packages/airflow/cli/commands/task_command.py", line 483, in task_run
    task_return_code = _run_task_by_selected_method(args, _dag, ti)
                       ^^^^^^^^^^^^^^^^^^^^^^^^^^^^^^^^^^^^^^^^^^^^
  File "/home/airflow/.local/lib/python3.12/site-packages/airflow/cli/commands/task_command.py", line 256, in _run_task_by_selected_method
    return _run_raw_task(args, ti)
           ^^^^^^^^^^^^^^^^^^^^^^^
  File "/home/airflow/.local/lib/python3.12/site-packages/airflow/cli/commands/task_command.py", line 341, in _run_raw_task
    return ti._run_raw_task(
           ^^^^^^^^^^^^^^^^^
  File "/home/airflow/.local/lib/python3.12/site-packages/airflow/utils/session.py", line 97, in wrapper
    return func(*args, session=session, **kwargs)
           ^^^^^^^^^^^^^^^^^^^^^^^^^^^^^^^^^^^^^^
  File "/home/airflow/.local/lib/python3.12/site-packages/airflow/models/taskinstance.py", line 3006, in _run_raw_task
    return _run_raw_task(
           ^^^^^^^^^^^^^^
  File "/home/airflow/.local/lib/python3.12/site-packages/airflow/models/taskinstance.py", line 274, in _run_raw_task
    TaskInstance._execute_task_with_callbacks(
  File "/home/airflow/.local/lib/python3.12/site-packages/airflow/models/taskinstance.py", line 3161, in _execute_task_with_callbacks
    result = self._execute_task(context, task_orig)
             ^^^^^^^^^^^^^^^^^^^^^^^^^^^^^^^^^^^^^^
  File "/home/airflow/.local/lib/python3.12/site-packages/airflow/models/taskinstance.py", line 3185, in _execute_task
    return _execute_task(self, context, task_orig)
           ^^^^^^^^^^^^^^^^^^^^^^^^^^^^^^^^^^^^^^^
  File "/home/airflow/.local/lib/python3.12/site-packages/airflow/models/taskinstance.py", line 763, in _execute_task
    result = _execute_callable(context=context, **execute_callable_kwargs)
             ^^^^^^^^^^^^^^^^^^^^^^^^^^^^^^^^^^^^^^^^^^^^^^^^^^^^^^^^^^^^^
  File "/home/airflow/.local/lib/python3.12/site-packages/airflow/models/taskinstance.py", line 734, in _execute_callable
    return ExecutionCallableRunner(
           ^^^^^^^^^^^^^^^^^^^^^^^^
  File "/home/airflow/.local/lib/python3.12/site-packages/airflow/utils/operator_helpers.py", line 252, in run
    return self.func(*args, **kwargs)
           ^^^^^^^^^^^^^^^^^^^^^^^^^^
  File "/home/airflow/.local/lib/python3.12/site-packages/airflow/models/baseoperator.py", line 424, in wrapper
    return func(self, *args, **kwargs)
           ^^^^^^^^^^^^^^^^^^^^^^^^^^^
  File "/home/airflow/.local/lib/python3.12/site-packages/airflow/operators/python.py", line 238, in execute
    return_value = self.execute_callable()
                   ^^^^^^^^^^^^^^^^^^^^^^^
  File "/home/airflow/.local/lib/python3.12/site-packages/airflow/operators/python.py", line 256, in execute_callable
    return runner.run(*self.op_args, **self.op_kwargs)
           ^^^^^^^^^^^^^^^^^^^^^^^^^^^^^^^^^^^^^^^^^^^
  File "/home/airflow/.local/lib/python3.12/site-packages/airflow/utils/operator_helpers.py", line 252, in run
    return self.func(*args, **kwargs)
           ^^^^^^^^^^^^^^^^^^^^^^^^^^
  File "/opt/airflow/dags/fraud_detection_training_dag.py", line 38, in train_model
    raise AirflowException(f'Model training failed: {str(e)}')
airflow.exceptions.AirflowException: Model training failed: NoBrokersAvailable
[2025-07-21T03:00:14.595+0000] {local_task_job_runner.py:266} INFO - Task exited with return code 1
[2025-07-21T03:00:14.619+0000] {taskinstance.py:3901} INFO - 1 downstream tasks scheduled from follow-on schedule check
[2025-07-21T03:00:14.621+0000] {local_task_job_runner.py:245} INFO - ::endgroup::
