[2025-06-20T08:23:56.615+0000] {local_task_job_runner.py:123} INFO - ::group::Pre task execution logs
[2025-06-20T08:23:56.638+0000] {taskinstance.py:2614} INFO - Dependencies all met for dep_context=non-requeueable deps ti=<TaskInstance: fraud_detection_training.execute_training manual__2025-06-20T08:23:53.574153+00:00 [queued]>
[2025-06-20T08:23:56.648+0000] {taskinstance.py:2614} INFO - Dependencies all met for dep_context=requeueable deps ti=<TaskInstance: fraud_detection_training.execute_training manual__2025-06-20T08:23:53.574153+00:00 [queued]>
[2025-06-20T08:23:56.649+0000] {taskinstance.py:2867} INFO - Starting attempt 1 of 1
[2025-06-20T08:23:56.662+0000] {taskinstance.py:2890} INFO - Executing <Task(PythonOperator): execute_training> on 2025-06-20 08:23:53.574153+00:00
[2025-06-20T08:23:56.669+0000] {warnings.py:112} WARNING - /home/***/.local/lib/python3.12/site-packages/***/task/task_runner/standard_task_runner.py:70: DeprecationWarning: This process (pid=29961) is multi-threaded, use of fork() may lead to deadlocks in the child.
  pid = os.fork()

[2025-06-20T08:23:56.671+0000] {standard_task_runner.py:72} INFO - Started process 29962 to run task
[2025-06-20T08:23:56.671+0000] {standard_task_runner.py:104} INFO - Running: ['***', 'tasks', 'run', 'fraud_detection_training', 'execute_training', 'manual__2025-06-20T08:23:53.574153+00:00', '--job-id', '72', '--raw', '--subdir', 'DAGS_FOLDER/fraud_detection_training_dag.py', '--cfg-path', '/tmp/tmpebttr3a2']
[2025-06-20T08:23:56.672+0000] {standard_task_runner.py:105} INFO - Job 72: Subtask execute_training
[2025-06-20T08:23:56.713+0000] {task_command.py:467} INFO - Running <TaskInstance: fraud_detection_training.execute_training manual__2025-06-20T08:23:53.574153+00:00 [running]> on host b6a56ce8a16d
[2025-06-20T08:23:56.794+0000] {taskinstance.py:3134} INFO - Exporting env vars: AIRFLOW_CTX_DAG_OWNER='Jasjot Parmar' AIRFLOW_CTX_DAG_ID='fraud_detection_training' AIRFLOW_CTX_TASK_ID='execute_training' AIRFLOW_CTX_EXECUTION_DATE='2025-06-20T08:23:53.574153+00:00' AIRFLOW_CTX_TRY_NUMBER='1' AIRFLOW_CTX_DAG_RUN_ID='manual__2025-06-20T08:23:53.574153+00:00'
[2025-06-20T08:23:56.796+0000] {taskinstance.py:732} INFO - ::endgroup::
[2025-06-20T08:23:56.812+0000] {fraud_detection_training_dag.py:23} INFO - Initializing fraud detection training...
[2025-06-20T08:24:03.889+0000] {fraud_detection_training_dag.py:26} INFO - Imported FraudDetectionTraining successfully.
[2025-06-20T08:24:03.902+0000] {fraud_detection_training.py:97} INFO - Configuration loaded successfully
[2025-06-20T08:24:04.541+0000] {fraud_detection_training.py:128} INFO - Minio connection verified. Buckets: ['mlflow']
[2025-06-20T08:24:05.016+0000] {fraud_detection_training_dag.py:29} INFO - Trainer initialized successfully.
[2025-06-20T08:24:05.017+0000] {fraud_detection_training.py:399} INFO - Starting model training process...
[2025-06-20T08:24:05.017+0000] {fraud_detection_training.py:144} INFO - Connecting to Kafka Topic: transactions
[2025-06-20T08:24:05.092+0000] {conn.py:396} INFO - <BrokerConnection client_id=kafka-python-2.2.11, node_id=bootstrap-0 host=pkc-ld537.ca-central-1.aws.confluent.cloud:9092 <connecting> [IPv4 ('15.157.158.196', 9092)]>: connecting to pkc-ld537.ca-central-1.aws.confluent.cloud:9092 [('15.157.158.196', 9092) IPv4]
[2025-06-20T08:24:05.162+0000] {conn.py:497} INFO - <BrokerConnection client_id=kafka-python-2.2.11, node_id=bootstrap-0 host=pkc-ld537.ca-central-1.aws.confluent.cloud:9092 <handshake> [IPv4 ('15.157.158.196', 9092)]>: Loading system default SSL CAs from ('/usr/lib/ssl/cert.pem', '/usr/lib/ssl/certs', 'SSL_CERT_FILE', '/usr/lib/ssl/cert.pem', 'SSL_CERT_DIR', '/usr/lib/ssl/certs')
[2025-06-20T08:24:05.412+0000] {conn.py:618} INFO - <BrokerConnection client_id=kafka-python-2.2.11, node_id=bootstrap-0 host=pkc-ld537.ca-central-1.aws.confluent.cloud:9092 <checking_api_versions_recv> [IPv4 ('15.157.158.196', 9092)]>: Broker version identified as 2.6
[2025-06-20T08:24:05.656+0000] {conn.py:822} INFO - <BrokerConnection client_id=kafka-python-2.2.11, node_id=bootstrap-0 host=pkc-ld537.ca-central-1.aws.confluent.cloud:9092 <authenticating> [IPv4 ('15.157.158.196', 9092)]>: Authenticated as VAWD3ORVNJTGIOBA via SASL / Plain
[2025-06-20T08:24:05.657+0000] {conn.py:467} INFO - <BrokerConnection client_id=kafka-python-2.2.11, node_id=bootstrap-0 host=pkc-ld537.ca-central-1.aws.confluent.cloud:9092 <connected> [IPv4 ('15.157.158.196', 9092)]>: Connection complete.
[2025-06-20T08:24:05.659+0000] {consumer.py:120} WARNING - group_id is None: disabling auto-commit.
[2025-06-20T08:24:05.659+0000] {subscription_state.py:181} INFO - Updating subscribed topics to: ('transactions',)
[2025-06-20T08:24:05.732+0000] {subscription_state.py:254} INFO - Updated partition assignment: [('transactions', 0), ('transactions', 1), ('transactions', 2), ('transactions', 3), ('transactions', 4), ('transactions', 5)]
[2025-06-20T08:24:05.770+0000] {conn.py:396} INFO - <BrokerConnection client_id=kafka-python-2.2.11, node_id=1 host=b1-pkc-ld537.ca-central-1.aws.confluent.cloud:9092 <connecting> [IPv4 ('35.182.170.137', 9092)]>: connecting to b1-pkc-ld537.ca-central-1.aws.confluent.cloud:9092 [('35.182.170.137', 9092) IPv4]
[2025-06-20T08:24:05.808+0000] {conn.py:396} INFO - <BrokerConnection client_id=kafka-python-2.2.11, node_id=2 host=b2-pkc-ld537.ca-central-1.aws.confluent.cloud:9092 <connecting> [IPv4 ('15.157.158.196', 9092)]>: connecting to b2-pkc-ld537.ca-central-1.aws.confluent.cloud:9092 [('15.157.158.196', 9092) IPv4]
[2025-06-20T08:24:05.842+0000] {conn.py:396} INFO - <BrokerConnection client_id=kafka-python-2.2.11, node_id=3 host=b3-pkc-ld537.ca-central-1.aws.confluent.cloud:9092 <connecting> [IPv4 ('15.223.160.19', 9092)]>: connecting to b3-pkc-ld537.ca-central-1.aws.confluent.cloud:9092 [('15.223.160.19', 9092) IPv4]
[2025-06-20T08:24:05.865+0000] {conn.py:396} INFO - <BrokerConnection client_id=kafka-python-2.2.11, node_id=5 host=b5-pkc-ld537.ca-central-1.aws.confluent.cloud:9092 <connecting> [IPv4 ('15.157.158.196', 9092)]>: connecting to b5-pkc-ld537.ca-central-1.aws.confluent.cloud:9092 [('15.157.158.196', 9092) IPv4]
[2025-06-20T08:24:05.888+0000] {conn.py:396} INFO - <BrokerConnection client_id=kafka-python-2.2.11, node_id=6 host=b6-pkc-ld537.ca-central-1.aws.confluent.cloud:9092 <connecting> [IPv4 ('15.223.160.19', 9092)]>: connecting to b6-pkc-ld537.ca-central-1.aws.confluent.cloud:9092 [('15.223.160.19', 9092) IPv4]
[2025-06-20T08:24:05.910+0000] {conn.py:396} INFO - <BrokerConnection client_id=kafka-python-2.2.11, node_id=7 host=b7-pkc-ld537.ca-central-1.aws.confluent.cloud:9092 <connecting> [IPv4 ('35.182.170.137', 9092)]>: connecting to b7-pkc-ld537.ca-central-1.aws.confluent.cloud:9092 [('35.182.170.137', 9092) IPv4]
[2025-06-20T08:24:05.911+0000] {conn.py:497} INFO - <BrokerConnection client_id=kafka-python-2.2.11, node_id=1 host=b1-pkc-ld537.ca-central-1.aws.confluent.cloud:9092 <handshake> [IPv4 ('35.182.170.137', 9092)]>: Loading system default SSL CAs from ('/usr/lib/ssl/cert.pem', '/usr/lib/ssl/certs', 'SSL_CERT_FILE', '/usr/lib/ssl/cert.pem', 'SSL_CERT_DIR', '/usr/lib/ssl/certs')
[2025-06-20T08:24:05.931+0000] {conn.py:497} INFO - <BrokerConnection client_id=kafka-python-2.2.11, node_id=2 host=b2-pkc-ld537.ca-central-1.aws.confluent.cloud:9092 <handshake> [IPv4 ('15.157.158.196', 9092)]>: Loading system default SSL CAs from ('/usr/lib/ssl/cert.pem', '/usr/lib/ssl/certs', 'SSL_CERT_FILE', '/usr/lib/ssl/cert.pem', 'SSL_CERT_DIR', '/usr/lib/ssl/certs')
[2025-06-20T08:24:05.953+0000] {conn.py:497} INFO - <BrokerConnection client_id=kafka-python-2.2.11, node_id=3 host=b3-pkc-ld537.ca-central-1.aws.confluent.cloud:9092 <handshake> [IPv4 ('15.223.160.19', 9092)]>: Loading system default SSL CAs from ('/usr/lib/ssl/cert.pem', '/usr/lib/ssl/certs', 'SSL_CERT_FILE', '/usr/lib/ssl/cert.pem', 'SSL_CERT_DIR', '/usr/lib/ssl/certs')
[2025-06-20T08:24:05.980+0000] {conn.py:497} INFO - <BrokerConnection client_id=kafka-python-2.2.11, node_id=5 host=b5-pkc-ld537.ca-central-1.aws.confluent.cloud:9092 <handshake> [IPv4 ('15.157.158.196', 9092)]>: Loading system default SSL CAs from ('/usr/lib/ssl/cert.pem', '/usr/lib/ssl/certs', 'SSL_CERT_FILE', '/usr/lib/ssl/cert.pem', 'SSL_CERT_DIR', '/usr/lib/ssl/certs')
[2025-06-20T08:24:06.007+0000] {conn.py:497} INFO - <BrokerConnection client_id=kafka-python-2.2.11, node_id=6 host=b6-pkc-ld537.ca-central-1.aws.confluent.cloud:9092 <handshake> [IPv4 ('15.223.160.19', 9092)]>: Loading system default SSL CAs from ('/usr/lib/ssl/cert.pem', '/usr/lib/ssl/certs', 'SSL_CERT_FILE', '/usr/lib/ssl/cert.pem', 'SSL_CERT_DIR', '/usr/lib/ssl/certs')
[2025-06-20T08:24:06.029+0000] {conn.py:497} INFO - <BrokerConnection client_id=kafka-python-2.2.11, node_id=7 host=b7-pkc-ld537.ca-central-1.aws.confluent.cloud:9092 <handshake> [IPv4 ('35.182.170.137', 9092)]>: Loading system default SSL CAs from ('/usr/lib/ssl/cert.pem', '/usr/lib/ssl/certs', 'SSL_CERT_FILE', '/usr/lib/ssl/cert.pem', 'SSL_CERT_DIR', '/usr/lib/ssl/certs')
[2025-06-20T08:24:06.315+0000] {conn.py:822} INFO - <BrokerConnection client_id=kafka-python-2.2.11, node_id=1 host=b1-pkc-ld537.ca-central-1.aws.confluent.cloud:9092 <authenticating> [IPv4 ('35.182.170.137', 9092)]>: Authenticated as VAWD3ORVNJTGIOBA via SASL / Plain
[2025-06-20T08:24:06.315+0000] {conn.py:467} INFO - <BrokerConnection client_id=kafka-python-2.2.11, node_id=1 host=b1-pkc-ld537.ca-central-1.aws.confluent.cloud:9092 <connected> [IPv4 ('35.182.170.137', 9092)]>: Connection complete.
[2025-06-20T08:24:06.316+0000] {conn.py:945} INFO - <BrokerConnection client_id=kafka-python-2.2.11, node_id=bootstrap-0 host=pkc-ld537.ca-central-1.aws.confluent.cloud:9092 <connected> [IPv4 ('15.157.158.196', 9092)]>: Closing connection. 
[2025-06-20T08:24:06.493+0000] {conn.py:822} INFO - <BrokerConnection client_id=kafka-python-2.2.11, node_id=2 host=b2-pkc-ld537.ca-central-1.aws.confluent.cloud:9092 <authenticating> [IPv4 ('15.157.158.196', 9092)]>: Authenticated as VAWD3ORVNJTGIOBA via SASL / Plain
[2025-06-20T08:24:06.494+0000] {conn.py:467} INFO - <BrokerConnection client_id=kafka-python-2.2.11, node_id=2 host=b2-pkc-ld537.ca-central-1.aws.confluent.cloud:9092 <connected> [IPv4 ('15.157.158.196', 9092)]>: Connection complete.
[2025-06-20T08:24:06.675+0000] {conn.py:822} INFO - <BrokerConnection client_id=kafka-python-2.2.11, node_id=3 host=b3-pkc-ld537.ca-central-1.aws.confluent.cloud:9092 <authenticating> [IPv4 ('15.223.160.19', 9092)]>: Authenticated as VAWD3ORVNJTGIOBA via SASL / Plain
[2025-06-20T08:24:06.675+0000] {conn.py:467} INFO - <BrokerConnection client_id=kafka-python-2.2.11, node_id=3 host=b3-pkc-ld537.ca-central-1.aws.confluent.cloud:9092 <connected> [IPv4 ('15.223.160.19', 9092)]>: Connection complete.
[2025-06-20T08:24:06.846+0000] {conn.py:822} INFO - <BrokerConnection client_id=kafka-python-2.2.11, node_id=5 host=b5-pkc-ld537.ca-central-1.aws.confluent.cloud:9092 <authenticating> [IPv4 ('15.157.158.196', 9092)]>: Authenticated as VAWD3ORVNJTGIOBA via SASL / Plain
[2025-06-20T08:24:06.847+0000] {conn.py:467} INFO - <BrokerConnection client_id=kafka-python-2.2.11, node_id=5 host=b5-pkc-ld537.ca-central-1.aws.confluent.cloud:9092 <connected> [IPv4 ('15.157.158.196', 9092)]>: Connection complete.
[2025-06-20T08:24:07.018+0000] {conn.py:822} INFO - <BrokerConnection client_id=kafka-python-2.2.11, node_id=6 host=b6-pkc-ld537.ca-central-1.aws.confluent.cloud:9092 <authenticating> [IPv4 ('15.223.160.19', 9092)]>: Authenticated as VAWD3ORVNJTGIOBA via SASL / Plain
[2025-06-20T08:24:07.019+0000] {conn.py:467} INFO - <BrokerConnection client_id=kafka-python-2.2.11, node_id=6 host=b6-pkc-ld537.ca-central-1.aws.confluent.cloud:9092 <connected> [IPv4 ('15.223.160.19', 9092)]>: Connection complete.
[2025-06-20T08:24:07.189+0000] {conn.py:822} INFO - <BrokerConnection client_id=kafka-python-2.2.11, node_id=7 host=b7-pkc-ld537.ca-central-1.aws.confluent.cloud:9092 <authenticating> [IPv4 ('35.182.170.137', 9092)]>: Authenticated as VAWD3ORVNJTGIOBA via SASL / Plain
[2025-06-20T08:24:07.190+0000] {conn.py:467} INFO - <BrokerConnection client_id=kafka-python-2.2.11, node_id=7 host=b7-pkc-ld537.ca-central-1.aws.confluent.cloud:9092 <connected> [IPv4 ('35.182.170.137', 9092)]>: Connection complete.
[2025-06-20T08:24:07.191+0000] {fetcher.py:418} INFO - Resetting offset for partition ('transactions', 1) to offset 0.
[2025-06-20T08:24:07.193+0000] {fetcher.py:418} INFO - Resetting offset for partition ('transactions', 5) to offset 0.
[2025-06-20T08:24:07.194+0000] {fetcher.py:418} INFO - Resetting offset for partition ('transactions', 3) to offset 0.
[2025-06-20T08:24:07.262+0000] {fetcher.py:418} INFO - Resetting offset for partition ('transactions', 2) to offset 0.
[2025-06-20T08:24:07.264+0000] {fetcher.py:418} INFO - Resetting offset for partition ('transactions', 4) to offset 0.
[2025-06-20T08:24:07.265+0000] {fetcher.py:418} INFO - Resetting offset for partition ('transactions', 0) to offset 0.
[2025-06-20T08:25:15.154+0000] {conn.py:945} INFO - <BrokerConnection client_id=kafka-python-2.2.11, node_id=1 host=b1-pkc-ld537.ca-central-1.aws.confluent.cloud:9092 <connected> [IPv4 ('35.182.170.137', 9092)]>: Closing connection. 
[2025-06-20T08:25:15.156+0000] {fetcher.py:784} INFO - Fetch to node 1 failed: Cancelled: <BrokerConnection client_id=kafka-python-2.2.11, node_id=1 host=b1-pkc-ld537.ca-central-1.aws.confluent.cloud:9092 <connected> [IPv4 ('35.182.170.137', 9092)]>
[2025-06-20T08:25:15.156+0000] {conn.py:945} INFO - <BrokerConnection client_id=kafka-python-2.2.11, node_id=2 host=b2-pkc-ld537.ca-central-1.aws.confluent.cloud:9092 <connected> [IPv4 ('15.157.158.196', 9092)]>: Closing connection. 
[2025-06-20T08:25:15.157+0000] {fetcher.py:784} INFO - Fetch to node 2 failed: Cancelled: <BrokerConnection client_id=kafka-python-2.2.11, node_id=2 host=b2-pkc-ld537.ca-central-1.aws.confluent.cloud:9092 <connected> [IPv4 ('15.157.158.196', 9092)]>
[2025-06-20T08:25:15.158+0000] {conn.py:945} INFO - <BrokerConnection client_id=kafka-python-2.2.11, node_id=3 host=b3-pkc-ld537.ca-central-1.aws.confluent.cloud:9092 <connected> [IPv4 ('15.223.160.19', 9092)]>: Closing connection. 
[2025-06-20T08:25:15.158+0000] {fetcher.py:784} INFO - Fetch to node 3 failed: Cancelled: <BrokerConnection client_id=kafka-python-2.2.11, node_id=3 host=b3-pkc-ld537.ca-central-1.aws.confluent.cloud:9092 <connected> [IPv4 ('15.223.160.19', 9092)]>
[2025-06-20T08:25:15.159+0000] {conn.py:945} INFO - <BrokerConnection client_id=kafka-python-2.2.11, node_id=5 host=b5-pkc-ld537.ca-central-1.aws.confluent.cloud:9092 <connected> [IPv4 ('15.157.158.196', 9092)]>: Closing connection. 
[2025-06-20T08:25:15.159+0000] {fetcher.py:784} INFO - Fetch to node 5 failed: Cancelled: <BrokerConnection client_id=kafka-python-2.2.11, node_id=5 host=b5-pkc-ld537.ca-central-1.aws.confluent.cloud:9092 <connected> [IPv4 ('15.157.158.196', 9092)]>
[2025-06-20T08:25:15.160+0000] {conn.py:945} INFO - <BrokerConnection client_id=kafka-python-2.2.11, node_id=6 host=b6-pkc-ld537.ca-central-1.aws.confluent.cloud:9092 <connected> [IPv4 ('15.223.160.19', 9092)]>: Closing connection. 
[2025-06-20T08:25:15.161+0000] {fetcher.py:784} INFO - Fetch to node 6 failed: Cancelled: <BrokerConnection client_id=kafka-python-2.2.11, node_id=6 host=b6-pkc-ld537.ca-central-1.aws.confluent.cloud:9092 <connected> [IPv4 ('15.223.160.19', 9092)]>
[2025-06-20T08:25:15.161+0000] {conn.py:945} INFO - <BrokerConnection client_id=kafka-python-2.2.11, node_id=7 host=b7-pkc-ld537.ca-central-1.aws.confluent.cloud:9092 <connected> [IPv4 ('35.182.170.137', 9092)]>: Closing connection. 
[2025-06-20T08:25:15.162+0000] {fetcher.py:784} INFO - Fetch to node 7 failed: Cancelled: <BrokerConnection client_id=kafka-python-2.2.11, node_id=7 host=b7-pkc-ld537.ca-central-1.aws.confluent.cloud:9092 <connected> [IPv4 ('35.182.170.137', 9092)]>
[2025-06-20T08:25:17.389+0000] {fraud_detection_training.py:177} INFO - Kafka data read successfully with fraud rate: 6.10
[2025-06-20T08:25:44.352+0000] {fraud_detection_training.py:596} ERROR - Training failed: cannot reindex on an axis with duplicate labels
Traceback (most recent call last):
  File "/opt/airflow/dags/fraud_detection_training.py", line 405, in train_model
    data = self.create_features(df)
           ^^^^^^^^^^^^^^^^^^^^^^^^
  File "/opt/airflow/dags/fraud_detection_training.py", line 284, in create_features
    df['amount_7d_avg'] = (
    ~~^^^^^^^^^^^^^^^^^
  File "/home/airflow/.local/lib/python3.12/site-packages/pandas/core/frame.py", line 4091, in __setitem__
    self._set_item(key, value)
  File "/home/airflow/.local/lib/python3.12/site-packages/pandas/core/frame.py", line 4300, in _set_item
    value, refs = self._sanitize_column(value)
                  ^^^^^^^^^^^^^^^^^^^^^^^^^^^^
  File "/home/airflow/.local/lib/python3.12/site-packages/pandas/core/frame.py", line 5036, in _sanitize_column
    return _reindex_for_setitem(value, self.index)
           ^^^^^^^^^^^^^^^^^^^^^^^^^^^^^^^^^^^^^^^
  File "/home/airflow/.local/lib/python3.12/site-packages/pandas/core/frame.py", line 12309, in _reindex_for_setitem
    raise err
  File "/home/airflow/.local/lib/python3.12/site-packages/pandas/core/frame.py", line 12304, in _reindex_for_setitem
    reindexed_value = value.reindex(index)._values
                      ^^^^^^^^^^^^^^^^^^^^
  File "/home/airflow/.local/lib/python3.12/site-packages/pandas/core/series.py", line 4981, in reindex
    return super().reindex(
           ^^^^^^^^^^^^^^^^
  File "/home/airflow/.local/lib/python3.12/site-packages/pandas/core/generic.py", line 5521, in reindex
    return self._reindex_axes(
           ^^^^^^^^^^^^^^^^^^^
  File "/home/airflow/.local/lib/python3.12/site-packages/pandas/core/generic.py", line 5544, in _reindex_axes
    new_index, indexer = ax.reindex(
                         ^^^^^^^^^^^
  File "/home/airflow/.local/lib/python3.12/site-packages/pandas/core/indexes/base.py", line 4434, in reindex
    raise ValueError("cannot reindex on an axis with duplicate labels")
ValueError: cannot reindex on an axis with duplicate labels
[2025-06-20T08:25:44.383+0000] {fraud_detection_training_dag.py:37} ERROR - Training failed: cannot reindex on an axis with duplicate labels
Traceback (most recent call last):
  File "/opt/airflow/dags/fraud_detection_training_dag.py", line 32, in train_model
    model, precision = trainer.train_model()
                       ^^^^^^^^^^^^^^^^^^^^^
  File "/opt/airflow/dags/fraud_detection_training.py", line 405, in train_model
    data = self.create_features(df)
           ^^^^^^^^^^^^^^^^^^^^^^^^
  File "/opt/airflow/dags/fraud_detection_training.py", line 284, in create_features
    df['amount_7d_avg'] = (
    ~~^^^^^^^^^^^^^^^^^
  File "/home/airflow/.local/lib/python3.12/site-packages/pandas/core/frame.py", line 4091, in __setitem__
    self._set_item(key, value)
  File "/home/airflow/.local/lib/python3.12/site-packages/pandas/core/frame.py", line 4300, in _set_item
    value, refs = self._sanitize_column(value)
                  ^^^^^^^^^^^^^^^^^^^^^^^^^^^^
  File "/home/airflow/.local/lib/python3.12/site-packages/pandas/core/frame.py", line 5036, in _sanitize_column
    return _reindex_for_setitem(value, self.index)
           ^^^^^^^^^^^^^^^^^^^^^^^^^^^^^^^^^^^^^^^
  File "/home/airflow/.local/lib/python3.12/site-packages/pandas/core/frame.py", line 12309, in _reindex_for_setitem
    raise err
  File "/home/airflow/.local/lib/python3.12/site-packages/pandas/core/frame.py", line 12304, in _reindex_for_setitem
    reindexed_value = value.reindex(index)._values
                      ^^^^^^^^^^^^^^^^^^^^
  File "/home/airflow/.local/lib/python3.12/site-packages/pandas/core/series.py", line 4981, in reindex
    return super().reindex(
           ^^^^^^^^^^^^^^^^
  File "/home/airflow/.local/lib/python3.12/site-packages/pandas/core/generic.py", line 5521, in reindex
    return self._reindex_axes(
           ^^^^^^^^^^^^^^^^^^^
  File "/home/airflow/.local/lib/python3.12/site-packages/pandas/core/generic.py", line 5544, in _reindex_axes
    new_index, indexer = ax.reindex(
                         ^^^^^^^^^^^
  File "/home/airflow/.local/lib/python3.12/site-packages/pandas/core/indexes/base.py", line 4434, in reindex
    raise ValueError("cannot reindex on an axis with duplicate labels")
ValueError: cannot reindex on an axis with duplicate labels
[2025-06-20T08:25:44.640+0000] {taskinstance.py:3313} ERROR - Task failed with exception
Traceback (most recent call last):
  File "/opt/airflow/dags/fraud_detection_training_dag.py", line 32, in train_model
    model, precision = trainer.train_model()
                       ^^^^^^^^^^^^^^^^^^^^^
  File "/opt/airflow/dags/fraud_detection_training.py", line 405, in train_model
    data = self.create_features(df)
           ^^^^^^^^^^^^^^^^^^^^^^^^
  File "/opt/airflow/dags/fraud_detection_training.py", line 284, in create_features
    df['amount_7d_avg'] = (
    ~~^^^^^^^^^^^^^^^^^
  File "/home/airflow/.local/lib/python3.12/site-packages/pandas/core/frame.py", line 4091, in __setitem__
    self._set_item(key, value)
  File "/home/airflow/.local/lib/python3.12/site-packages/pandas/core/frame.py", line 4300, in _set_item
    value, refs = self._sanitize_column(value)
                  ^^^^^^^^^^^^^^^^^^^^^^^^^^^^
  File "/home/airflow/.local/lib/python3.12/site-packages/pandas/core/frame.py", line 5036, in _sanitize_column
    return _reindex_for_setitem(value, self.index)
           ^^^^^^^^^^^^^^^^^^^^^^^^^^^^^^^^^^^^^^^
  File "/home/airflow/.local/lib/python3.12/site-packages/pandas/core/frame.py", line 12309, in _reindex_for_setitem
    raise err
  File "/home/airflow/.local/lib/python3.12/site-packages/pandas/core/frame.py", line 12304, in _reindex_for_setitem
    reindexed_value = value.reindex(index)._values
                      ^^^^^^^^^^^^^^^^^^^^
  File "/home/airflow/.local/lib/python3.12/site-packages/pandas/core/series.py", line 4981, in reindex
    return super().reindex(
           ^^^^^^^^^^^^^^^^
  File "/home/airflow/.local/lib/python3.12/site-packages/pandas/core/generic.py", line 5521, in reindex
    return self._reindex_axes(
           ^^^^^^^^^^^^^^^^^^^
  File "/home/airflow/.local/lib/python3.12/site-packages/pandas/core/generic.py", line 5544, in _reindex_axes
    new_index, indexer = ax.reindex(
                         ^^^^^^^^^^^
  File "/home/airflow/.local/lib/python3.12/site-packages/pandas/core/indexes/base.py", line 4434, in reindex
    raise ValueError("cannot reindex on an axis with duplicate labels")
ValueError: cannot reindex on an axis with duplicate labels

During handling of the above exception, another exception occurred:

Traceback (most recent call last):
  File "/home/airflow/.local/lib/python3.12/site-packages/airflow/models/taskinstance.py", line 763, in _execute_task
    result = _execute_callable(context=context, **execute_callable_kwargs)
             ^^^^^^^^^^^^^^^^^^^^^^^^^^^^^^^^^^^^^^^^^^^^^^^^^^^^^^^^^^^^^
  File "/home/airflow/.local/lib/python3.12/site-packages/airflow/models/taskinstance.py", line 734, in _execute_callable
    return ExecutionCallableRunner(
           ^^^^^^^^^^^^^^^^^^^^^^^^
  File "/home/airflow/.local/lib/python3.12/site-packages/airflow/utils/operator_helpers.py", line 252, in run
    return self.func(*args, **kwargs)
           ^^^^^^^^^^^^^^^^^^^^^^^^^^
  File "/home/airflow/.local/lib/python3.12/site-packages/airflow/models/baseoperator.py", line 424, in wrapper
    return func(self, *args, **kwargs)
           ^^^^^^^^^^^^^^^^^^^^^^^^^^^
  File "/home/airflow/.local/lib/python3.12/site-packages/airflow/operators/python.py", line 238, in execute
    return_value = self.execute_callable()
                   ^^^^^^^^^^^^^^^^^^^^^^^
  File "/home/airflow/.local/lib/python3.12/site-packages/airflow/operators/python.py", line 256, in execute_callable
    return runner.run(*self.op_args, **self.op_kwargs)
           ^^^^^^^^^^^^^^^^^^^^^^^^^^^^^^^^^^^^^^^^^^^
  File "/home/airflow/.local/lib/python3.12/site-packages/airflow/utils/operator_helpers.py", line 252, in run
    return self.func(*args, **kwargs)
           ^^^^^^^^^^^^^^^^^^^^^^^^^^
  File "/opt/airflow/dags/fraud_detection_training_dag.py", line 38, in train_model
    raise AirflowException(f'Model training failed: {str(e)}')
airflow.exceptions.AirflowException: Model training failed: cannot reindex on an axis with duplicate labels
[2025-06-20T08:25:44.650+0000] {taskinstance.py:1226} INFO - Marking task as FAILED. dag_id=fraud_detection_training, task_id=execute_training, run_id=manual__2025-06-20T08:23:53.574153+00:00, execution_date=20250620T082353, start_date=20250620T082356, end_date=20250620T082544
[2025-06-20T08:25:44.684+0000] {taskinstance.py:341} INFO - ::group::Post task execution logs
[2025-06-20T08:25:44.685+0000] {standard_task_runner.py:124} ERROR - Failed to execute job 72 for task execute_training (Model training failed: cannot reindex on an axis with duplicate labels; 29962)
Traceback (most recent call last):
  File "/opt/airflow/dags/fraud_detection_training_dag.py", line 32, in train_model
    model, precision = trainer.train_model()
                       ^^^^^^^^^^^^^^^^^^^^^
  File "/opt/airflow/dags/fraud_detection_training.py", line 405, in train_model
    data = self.create_features(df)
           ^^^^^^^^^^^^^^^^^^^^^^^^
  File "/opt/airflow/dags/fraud_detection_training.py", line 284, in create_features
    df['amount_7d_avg'] = (
    ~~^^^^^^^^^^^^^^^^^
  File "/home/airflow/.local/lib/python3.12/site-packages/pandas/core/frame.py", line 4091, in __setitem__
    self._set_item(key, value)
  File "/home/airflow/.local/lib/python3.12/site-packages/pandas/core/frame.py", line 4300, in _set_item
    value, refs = self._sanitize_column(value)
                  ^^^^^^^^^^^^^^^^^^^^^^^^^^^^
  File "/home/airflow/.local/lib/python3.12/site-packages/pandas/core/frame.py", line 5036, in _sanitize_column
    return _reindex_for_setitem(value, self.index)
           ^^^^^^^^^^^^^^^^^^^^^^^^^^^^^^^^^^^^^^^
  File "/home/airflow/.local/lib/python3.12/site-packages/pandas/core/frame.py", line 12309, in _reindex_for_setitem
    raise err
  File "/home/airflow/.local/lib/python3.12/site-packages/pandas/core/frame.py", line 12304, in _reindex_for_setitem
    reindexed_value = value.reindex(index)._values
                      ^^^^^^^^^^^^^^^^^^^^
  File "/home/airflow/.local/lib/python3.12/site-packages/pandas/core/series.py", line 4981, in reindex
    return super().reindex(
           ^^^^^^^^^^^^^^^^
  File "/home/airflow/.local/lib/python3.12/site-packages/pandas/core/generic.py", line 5521, in reindex
    return self._reindex_axes(
           ^^^^^^^^^^^^^^^^^^^
  File "/home/airflow/.local/lib/python3.12/site-packages/pandas/core/generic.py", line 5544, in _reindex_axes
    new_index, indexer = ax.reindex(
                         ^^^^^^^^^^^
  File "/home/airflow/.local/lib/python3.12/site-packages/pandas/core/indexes/base.py", line 4434, in reindex
    raise ValueError("cannot reindex on an axis with duplicate labels")
ValueError: cannot reindex on an axis with duplicate labels

During handling of the above exception, another exception occurred:

Traceback (most recent call last):
  File "/home/airflow/.local/lib/python3.12/site-packages/airflow/task/task_runner/standard_task_runner.py", line 117, in _start_by_fork
    ret = args.func(args, dag=self.dag)
          ^^^^^^^^^^^^^^^^^^^^^^^^^^^^^
  File "/home/airflow/.local/lib/python3.12/site-packages/airflow/cli/cli_config.py", line 49, in command
    return func(*args, **kwargs)
           ^^^^^^^^^^^^^^^^^^^^^
  File "/home/airflow/.local/lib/python3.12/site-packages/airflow/utils/cli.py", line 116, in wrapper
    return f(*args, **kwargs)
           ^^^^^^^^^^^^^^^^^^
  File "/home/airflow/.local/lib/python3.12/site-packages/airflow/cli/commands/task_command.py", line 483, in task_run
    task_return_code = _run_task_by_selected_method(args, _dag, ti)
                       ^^^^^^^^^^^^^^^^^^^^^^^^^^^^^^^^^^^^^^^^^^^^
  File "/home/airflow/.local/lib/python3.12/site-packages/airflow/cli/commands/task_command.py", line 256, in _run_task_by_selected_method
    return _run_raw_task(args, ti)
           ^^^^^^^^^^^^^^^^^^^^^^^
  File "/home/airflow/.local/lib/python3.12/site-packages/airflow/cli/commands/task_command.py", line 341, in _run_raw_task
    return ti._run_raw_task(
           ^^^^^^^^^^^^^^^^^
  File "/home/airflow/.local/lib/python3.12/site-packages/airflow/utils/session.py", line 97, in wrapper
    return func(*args, session=session, **kwargs)
           ^^^^^^^^^^^^^^^^^^^^^^^^^^^^^^^^^^^^^^
  File "/home/airflow/.local/lib/python3.12/site-packages/airflow/models/taskinstance.py", line 3006, in _run_raw_task
    return _run_raw_task(
           ^^^^^^^^^^^^^^
  File "/home/airflow/.local/lib/python3.12/site-packages/airflow/models/taskinstance.py", line 274, in _run_raw_task
    TaskInstance._execute_task_with_callbacks(
  File "/home/airflow/.local/lib/python3.12/site-packages/airflow/models/taskinstance.py", line 3161, in _execute_task_with_callbacks
    result = self._execute_task(context, task_orig)
             ^^^^^^^^^^^^^^^^^^^^^^^^^^^^^^^^^^^^^^
  File "/home/airflow/.local/lib/python3.12/site-packages/airflow/models/taskinstance.py", line 3185, in _execute_task
    return _execute_task(self, context, task_orig)
           ^^^^^^^^^^^^^^^^^^^^^^^^^^^^^^^^^^^^^^^
  File "/home/airflow/.local/lib/python3.12/site-packages/airflow/models/taskinstance.py", line 763, in _execute_task
    result = _execute_callable(context=context, **execute_callable_kwargs)
             ^^^^^^^^^^^^^^^^^^^^^^^^^^^^^^^^^^^^^^^^^^^^^^^^^^^^^^^^^^^^^
  File "/home/airflow/.local/lib/python3.12/site-packages/airflow/models/taskinstance.py", line 734, in _execute_callable
    return ExecutionCallableRunner(
           ^^^^^^^^^^^^^^^^^^^^^^^^
  File "/home/airflow/.local/lib/python3.12/site-packages/airflow/utils/operator_helpers.py", line 252, in run
    return self.func(*args, **kwargs)
           ^^^^^^^^^^^^^^^^^^^^^^^^^^
  File "/home/airflow/.local/lib/python3.12/site-packages/airflow/models/baseoperator.py", line 424, in wrapper
    return func(self, *args, **kwargs)
           ^^^^^^^^^^^^^^^^^^^^^^^^^^^
  File "/home/airflow/.local/lib/python3.12/site-packages/airflow/operators/python.py", line 238, in execute
    return_value = self.execute_callable()
                   ^^^^^^^^^^^^^^^^^^^^^^^
  File "/home/airflow/.local/lib/python3.12/site-packages/airflow/operators/python.py", line 256, in execute_callable
    return runner.run(*self.op_args, **self.op_kwargs)
           ^^^^^^^^^^^^^^^^^^^^^^^^^^^^^^^^^^^^^^^^^^^
  File "/home/airflow/.local/lib/python3.12/site-packages/airflow/utils/operator_helpers.py", line 252, in run
    return self.func(*args, **kwargs)
           ^^^^^^^^^^^^^^^^^^^^^^^^^^
  File "/opt/airflow/dags/fraud_detection_training_dag.py", line 38, in train_model
    raise AirflowException(f'Model training failed: {str(e)}')
airflow.exceptions.AirflowException: Model training failed: cannot reindex on an axis with duplicate labels
[2025-06-20T08:25:44.791+0000] {local_task_job_runner.py:266} INFO - Task exited with return code 1
[2025-06-20T08:25:44.817+0000] {taskinstance.py:3901} INFO - 1 downstream tasks scheduled from follow-on schedule check
[2025-06-20T08:25:44.819+0000] {local_task_job_runner.py:245} INFO - ::endgroup::
